nohup: ignoring input
User 465, list index out of range list index out of range
User 456, list index out of range list index out of range
User 272, list index out of range list index out of range
User 328, list index out of range list index out of range
Traceback (most recent call last):
  File "main_da_vinci.py", line 370, in <module>
    movielens(model)
  File "main_da_vinci.py", line 237, in movielens
    send_message_for_movielens(ratings_path='../data/dataset/ml_small_2018/splitting/0/subset_train_200.tsv',
  File "main_da_vinci.py", line 66, in send_message_for_movielens
    message = "Given a user, act like a Recommender System." + utils.rerank_by_similar_user_profile(user, result)
  File "/home/dario/RecSys2023/Recommender-ChatGPT/code/utils/utils.py", line 356, in rerank_by_similar_user_profile
    user_knn = UserKnnLoader(path)
  File "/home/dario/RecSys2023/Recommender-ChatGPT/code/utils/load_userknn.py", line 64, in __init__
    self.load_weights(path)
  File "/home/dario/RecSys2023/Recommender-ChatGPT/code/utils/load_userknn.py", line 82, in load_weights
    with open(path, "rb") as f:
FileNotFoundError: [Errno 2] No such file or directory: '../results/user_knn_movielens_small_2018/UserKNN_nn=80_sim=correlation_imp=standard_bin=False_shrink=0_norm=True_asymalpha=_tvalpha=_tvbeta=_rweights=/best-weights-UserKNN_nn=80_sim=correlation_imp=standard_bin=False_shrink=0_norm=True_asymalpha=_tvalpha=_tvbeta=_rweights='

During handling of the above exception, another exception occurred:

Traceback (most recent call last):
  File "/home/dario/anaconda3/envs/Recommender-ChatGPT/lib/python3.8/smtplib.py", line 358, in send
    self.sock.sendall(s)
  File "/home/dario/anaconda3/envs/Recommender-ChatGPT/lib/python3.8/ssl.py", line 1204, in sendall
    v = self.send(byte_view[count:])
  File "/home/dario/anaconda3/envs/Recommender-ChatGPT/lib/python3.8/ssl.py", line 1173, in send
    return self._sslobj.write(data)
ConnectionResetError: [Errno 104] Connection reset by peer

During handling of the above exception, another exception occurred:

Traceback (most recent call last):
  File "main_da_vinci.py", line 374, in <module>
    server.send_message(message)
  File "/home/dario/anaconda3/envs/Recommender-ChatGPT/lib/python3.8/smtplib.py", line 984, in send_message
    return self.sendmail(from_addr, to_addrs, flatmsg, mail_options,
  File "/home/dario/anaconda3/envs/Recommender-ChatGPT/lib/python3.8/smtplib.py", line 879, in sendmail
    (code, resp) = self.mail(from_addr, esmtp_opts)
  File "/home/dario/anaconda3/envs/Recommender-ChatGPT/lib/python3.8/smtplib.py", line 543, in mail
    self.putcmd("mail", "FROM:%s%s" % (quoteaddr(sender), optionlist))
  File "/home/dario/anaconda3/envs/Recommender-ChatGPT/lib/python3.8/smtplib.py", line 376, in putcmd
    self.send(f'{s}{CRLF}')
  File "/home/dario/anaconda3/envs/Recommender-ChatGPT/lib/python3.8/smtplib.py", line 361, in send
    raise SMTPServerDisconnected('Server not connected')
smtplib.SMTPServerDisconnected: Server not connected

During handling of the above exception, another exception occurred:

Traceback (most recent call last):
  File "main_da_vinci.py", line 378, in <module>
    server.quit()
  File "/home/dario/anaconda3/envs/Recommender-ChatGPT/lib/python3.8/smtplib.py", line 1002, in quit
    res = self.docmd("quit")
  File "/home/dario/anaconda3/envs/Recommender-ChatGPT/lib/python3.8/smtplib.py", line 429, in docmd
    self.putcmd(cmd, args)
  File "/home/dario/anaconda3/envs/Recommender-ChatGPT/lib/python3.8/smtplib.py", line 376, in putcmd
    self.send(f'{s}{CRLF}')
  File "/home/dario/anaconda3/envs/Recommender-ChatGPT/lib/python3.8/smtplib.py", line 363, in send
    raise SMTPServerDisconnected('please run connect() first')
smtplib.SMTPServerDisconnected: please run connect() first
